Workbook

Sheet Capa
B2: PLANO DE TESTES
B3: JobsIA — Sistema de Geração Segura de Checklists e Validação de Normas
B5: Projeto | C5: JobsIA 2.0
B6: Documento | C6: Plano de Testes
B7: Versão | C7: 1.1
B8: Data de emissão | C8: 14/08/2026
B9: Autor | C9: Equipe de Qualidade JobsIA (dev@quantumtecnologia.com.br)
B10: Norma de referência | C10: N/PD/004/02 (nomenclatura e padronização de jobs corporativos)
B11: Revisão | C11: Incorpora os ajustes de docs/Documento_Cobertura_Testes_JobsIA_v2.docx e outputs/019fdc6d.../Cenario_de_Testes_JobsIA.xlsx (auditoria de cobertura de 07/08/2026).
B13: 1. Objetivo
B14: Definir o escopo, a estratégia, os critérios de entrada/saída e os casos de teste necessários para validar funcionalmente, em termos de segurança (RBAC) e de integração o sistema JobsIA: geração assistida de checklists de jobs corporativos, validação determinística de conformidade com a norma N/PD/004/02, gestão de dicionário e normas versionadas, geração de PDF e o assistente de IA (LIA).
B16: 2. Escopo (dentro do projeto)
B17: • RBAC nativo (ADMIN, OPERADOR, SOLICITANTE) e autenticação JWT própria (login, refresh, logout, signup).
B18: • Geração dinâmica de checklists (schema v1 legado e schema v2 por Application) e exportação em PDF.
B19: • Motor de validação determinístico da norma N/PD/004/02 (nomenclatura Unix/Windows/Mainframe, objetos SQL, fita magnética, Connect:Direct).
B20: • Gestão dinâmica de Dicionário de Termos e Normas com fluxo de aprovação/publicação/rollback.
B21: • Catálogo oficial de checklist (itens GENERIC/BRIDGE e regras de nomenclatura de Application) e importação pelo ADMIN.
B22: • Assistente de IA (LIA): chat, histórico de conversas, preferências de modelo e injeção de contexto normativo.
B23: • Auditoria de ações sensíveis e feedback de interação.
B24: • Segurança de migrações de banco de dados (proteção da tabela public.users e do volume em produção).
B26: 3. Fora de escopo
... B67: Este plano de execução manual/funcional permanece complementar a essa auditoria: ela cobre exclusivamente testes unitários isolados (mocks), enquanto este documento cobre também os cenários de integração, segurança dinâmica, PDF, migrações e interface que já possuem evidência de teste (ver coluna "Teste Automatizado" na aba "Casos de Teste").

Sheet Casos de Teste
A1: ID | B1: Módulo | C1: Funcionalidade / Endpoint | D1: Título do Caso de Teste | E1: Tipo | F1: Prioridade | G1: Perfil de Acesso | H1: Pré-condições | I1: Passos de Execução | J1: Dados de Entrada / Massa de Teste | K1: Resultado Esperado | L1: Teste Automatizado (referência) | M1: Status | N1: Observações
A2: CT-001 | B2: Autenticação | C2: POST /api/auth/login | D2: Login com credenciais válidas | E2: Funcional | F2: Alta | G2: Público (sem login) | H2: Usuário ativo cadastrado no banco de testes. | I2: 1. Enviar e-mail e senha corretos para POST /api/auth/login. 2. Inspecionar corpo e headers da resposta. | J2: { email, password } de usuário ativo válido. | K2: HTTP 200; resposta contém access token JWT, refresh token e dados do perfil (id, nome, e-mail, role). | L2: server/tests/auth_cycle.test.ts | M2: A executar
A3: CT-002 | B3: Autenticação | C3: POST /api/auth/login | D3: Login de usuário inativo é bloqueado | E3: Funcional | F3: Alta | G3: Público (sem login) | H3: Usuário existente com status inativo. | I3: 1. Enviar credenciais de usuário inativo para POST /api/auth/login. | J3: { email, password } de usuário com is_active = false. | K3: HTTP 401/403; login recusado com mensagem apropriada; nenhum token emitido. | L3: server/tests/auth_cycle.test.ts; server/tests/rbac.test.ts | M3: A executar
A4: CT-003 | B4: Autenticação | C4: POST /api/auth/login | D4: Login com senha incorreta é rejeitado | E4: Segurança | F4: Alta | G4: Público (sem login) | H4: Usuário ativo cadastrado. | I4: 1. Enviar e-mail válido com senha incorreta. | J4: { email válido, password inválido }. | K4: HTTP 401; mensagem genérica que não revela se o e-mail existe ou não. | L4: Manual | M4: A executar
A5: CT-004 | B5: Autenticação | C5: GET /api/auth/me | D5: Perfil retornado com token válido | E5: Funcional | F5: Alta | G5: Autenticado (qualquer papel) | H5: Usuário autenticado com access token válido. | I5: 1. Chamar GET /api/auth/me com header Authorization: Bearer <token>. | J5: Token JWT válido não expirado. | K5: HTTP 200; retorna id, nome, e-mail e role atuais do usuário. | L5: server/tests/auth_cycle.test.ts | M5: A executar
A6: CT-005 | B6: Autenticação | C6: GET /api/auth/me | D6: Token inválido/expirado retorna 401 | E6: Segurança | F6: Alta | G6: Público (sem login) | H6: Nenhuma (token forjado ou expirado). | I6: 1. Chamar GET /api/auth/me com token inválido, expirado ou ausente. | J6: Token corrompido/expirado ou header ausente. | K6: HTTP 401 Unauthorized; nenhuma informação de perfil vazada. | L6: server/tests/auth_cycle.test.ts; server/tests/rbac.test.ts | M6: A executar
A7: CT-006 | B7: Autenticação | C7: POST /api/auth/refresh + /logout | D7: Ciclo completo de renovação e revogação de tokens | E7: Integração | F7: Alta | G7: Autenticado (qualquer papel) | H7: Usuário autenticado possui refresh token válido emitido no login. | I7: 1. Chamar POST /api/auth/refresh com refresh token válido. 2. Confirmar emissão de novo access token. 3. Chamar POST /api/auth/logout. 4. Tentar novo refresh com o mesmo token revogado. | J7: Refresh token válido obtido no login. | K7: Refresh emite novo access token; após logout, o refresh token é revogado e um novo /refresh com o mesmo token falha. | L7: server/tests/auth_cycle.test.ts | M7: A executar
A8: CT-007 | B8: Autenticação | C8: POST /api/auth/signup | D8: Cadastro público cria usuário com papel padrão SOLICITANTE | E8: Funcional | F8: Alta | G8: Público (sem login) | H8: E-mail ainda não cadastrado na base. | I8: 1. Enviar nome, e-mail e senha para POST /api/auth/signup. 2. Consultar o papel do usuário criado. | J8: { name, email, password } de conta nova. | K8: HTTP 201; usuário criado com role = SOLICITANTE independentemente do papel enviado no payload. | L8: server/tests/rbac.test.ts | M8: A executar
A9: CT-008 | B9: Autenticação | C9: Rotas protegidas | D9: Requisição sem token é rejeitada | E9: Segurança | F9: Alta | G9: Público (sem login) | H9: Nenhuma. | I9: 1. Chamar rota protegida (ex.: GET /api/checklists) sem header Authorization. | J9: Requisição sem token. | K9: HTTP 401 Unauthorized. | L9: server/tests/rbac.test.ts | M9: A executar
A10: CT-009 | B10: Autenticação | C10: Promoção a ADMIN | D10: Primeiro usuário ADMIN é promovido via UPDATE SQL e reflete no login seguinte | E10: Funcional | F10: Média | G10: ADMIN | H10: Usuário SOLICITANTE cadastrado via /signup; acesso direto ao PostgreSQL. | I10: 1. Executar UPDATE users SET role='ADMIN' WHERE email=... . 2. Logout e novo login do usuário. 3. Verificar GET /api/auth/me. | J10: UPDATE SQL conforme README + credenciais do usuário. | K10: Após novo login, o token/perfil refletem role = ADMIN e o painel administrativo fica acessível. | L10: Manual | M10: A executar
A11: CT-010 | B11: Autenticação | C11: Token de usuário desativado em sessão ativa | D11: Sessão de usuário desativado deixa de ser aceita | E11: Segurança | F11: Alta | G11: Autenticado (qualquer papel) | H11: Usuário autenticado com sessão ativa; ADMIN desativa a conta em seguida. | I11: 1. Autenticar usuário e guardar token. 2. ADMIN desativa o usuário (is_active=false). 3. Reutilizar o token antigo em rota protegida. | J11: Token emitido antes da desativação. | K11: HTTP 401; acesso recusado mesmo com token ainda não expirado. | L11: server/tests/rbac.test.ts | M11: A executar
A12: CT-011 | B12: RBAC / Autorização | C12: POST /api/norms | D12: SOLICITANTE não pode criar normas | E12: Segurança | F12: Alta | G12: SOLICITANTE | H12: Usuário autenticado com papel SOLICITANTE. | I12: 1. Autenticar como SOLICITANTE. 2. Chamar POST /api/norms com payload válido de norma. | J12: Payload de norma válido. | K12: HTTP 403 Forbidden; norma não é persistida. | L12: server/tests/rbac.test.ts | M12: A executar
A13: CT-012 | B13: RBAC / Autorização | C13: POST /api/norms | D13: OPERADOR não pode criar normas | E13: Segurança | F13: Alta | G13: OPERADOR | H13: Usuário autenticado com papel OPERADOR. | I13: 1. Autenticar como OPERADOR. 2. Chamar POST /api/norms com payload válido. | J13: Payload de norma válido. | K13: HTTP 403 Forbidden; norma não é persistida. | L13: server/tests/rbac.test.ts | M13: A executar
... A20: CT-019 | B20: RBAC / Autorização | C20: PUT /api/norms/:id/applicability | D20: Alteração de aplicabilidade de norma é restrita a ADMIN e gera auditoria | E20: Segurança | F20: Alta | G20: ADMIN | H20: Norma existente cadastrada; usuário ADMIN autenticado. | I20: 1. Tentar alterar aplicabilidade como OPERADOR (esperar 403). 2. Alterar como ADMIN. 3. Consultar JobsIA_audit_logs. | J20: Payload de escopo de aplicabilidade (job types). | K20: Não-ADMIN recebe 403; ADMIN altera com sucesso (200) e um registro de auditoria é criado com usuário, IP e payload. | L20: server/tests/rbac.test.ts | M20: A executar
A21: CT-020 | B21: RBAC / Autorização | C21: GET /api/checklists | D21: SOLICITANTE visualiza apenas os próprios checklists | E21: Segurança | F21: Alta | G21: SOLICITANTE | H21: Existem checklists de múltiplos usuários no banco de testes. | I21: 1. Autenticar como SOLICITANTE A. 2. Chamar GET /api/checklists. | J21: — | K21: Retorna somente os checklists criados pelo próprio usuário autenticado. | L21: server/tests/rbac.test.ts | M21: A executar | N21: Cobertura de código real do arquivo (checklists.ts) é Parcial (3,88% linhas) — ver GAP-001.
A22: CT-021 | B22: RBAC / Autorização | C22: GET /api/checklists?userId= | D22: Tentativa de SOLICITANTE filtrar checklist de terceiros é ignorada/rejeitada | E22: Segurança | F22: Alta | G22: SOLICITANTE | H22: Existem checklists de outro usuário. | I22: 1. Autenticar como SOLICITANTE A. 2. Chamar GET /api/checklists?userId=<id de outro usuário>. | J22: userId de outro usuário na query string. | K22: O parâmetro é ignorado ou rejeitado; resposta continua restrita aos checklists do próprio usuário autenticado. | L22: server/tests/rbac.test.ts | M22: A executar | N22: Cobertura de código real do arquivo (checklists.ts) é Parcial (3,88% linhas) — ver GAP-001.
A23: CT-022 | B23: RBAC / Autorização | C23: GET /api/checklists?userId= | D23: OPERADOR consegue ver todos os checklists ou filtrar por usuário | E23: Funcional | F23: Média | G23: OPERADOR | H23: Existem checklists de múltiplos usuários. | I23: 1. Autenticar como OPERADOR. 2. Chamar GET /api/checklists sem filtro e depois com userId específico. | J23: userId válido de outro usuário. | K23: Sem filtro retorna todos os checklists; com filtro retorna apenas os do usuário indicado. | L23: server/tests/rbac.test.ts | M23: A executar | N23: Cobertura de código real do arquivo (checklists.ts) é Parcial (3,88% linhas) — ver GAP-001.
A24: CT-023 | B24: RBAC / Autorização | C24: POST /api/checklists | D24: user_id do checklist é derivado do JWT, ignorando o payload do cliente | E24: Segurança | F24: Alta | G24: SOLICITANTE | H24: Usuário SOLICITANTE autenticado. | I24: 1. Autenticar como usuário A. 2. Enviar POST /api/checklists com user_id de outro usuário no corpo da requisição. | J24: Payload de checklist válido contendo user_id forjado de outro usuário. | K24: O checklist criado pertence ao usuário do token (A), independentemente do user_id enviado no payload. | L24: server/tests/rbac.test.ts | M24: A executar | N24: Cobertura de código real do arquivo (checklists.ts) é Parcial (3,88% linhas) — ver GAP-002.
A25: CT-024 | B25: RBAC / Autorização | C25: POST /api/dictionary | D25: Dicionário bloqueia criação de termo por SOLICITANTE | E25: Segurança | F25: Alta | G25: SOLICITANTE | H25: Usuário autenticado como SOLICITANTE. | I25: 1. Chamar POST /api/dictionary com payload válido de termo. | J25: Payload válido de termo do dicionário. | K25: HTTP 403 Forbidden; termo não é persistido. | L25: server/tests/critical_routes.unit.test.ts | M25: A executar
A26: CT-025 | B26: Usuários | C26: POST /api/users | D26: ADMIN cadastra novo usuário informando papel | E26: Funcional | F26: Média | G26: ADMIN | H26: Usuário ADMIN autenticado. | I26: 1. Chamar POST /api/users com nome, e-mail, senha e role. | J26: { name, email, password, role }. | K26: HTTP 201; usuário criado com o papel informado. | L26: server/tests/auth_cycle.test.ts | M26: A executar
A27: CT-026 | B27: Usuários | C27: PUT /api/users/:id | D27: Atualização de dados/papel de um usuário existente | E27: Funcional | F27: Média | G27: ADMIN | H27: Usuário existente no banco de testes; ADMIN autenticado. | I27: 1. Chamar PUT /api/users/:id alterando nome e/ou role. | J27: { name?, role?, is_active? } parcial. | K27: HTTP 200; alterações persistidas e refletidas em consultas subsequentes. | L27: Manual | M27: A executar | N27: Sem teste automatizado direto (users.ts com 6,72% linhas) — ver GAP-019.
A28: CT-027 | B28: Usuários | C28: POST /api/users | D28: Criação transacional de usuário sofre rollback em caso de erro | E28: Integração | F28: Média | G28: ADMIN | H28: Cenário forçando falha no meio da transação (ex.: violação de constraint). | I28: 1. Enviar payload que provoque erro após a etapa inicial da transação (ex.: e-mail duplicado). | J28: Payload com e-mail já existente. | K28: Nenhum registro parcial é gravado; a transação é revertida integralmente e erro apropriado é retornado. | L28: server/tests/auth_cycle.test.ts | M28: A executar
A29: CT-028 | B29: Dicionário de Termos | C29: GET /api/dictionary | D29: Listagem pública de termos do dicionário | E29: Funcional | F29: Média | G29: Público (sem login) | H29: Existem termos publicados. | I29: 1. Chamar GET /api/dictionary sem autenticação. | J29: — | K29: HTTP 200; retorna termos vigentes (publicados). | L29: Manual | M29: A executar
A30: CT-029 | B30: Dicionário de Termos | C30: POST /api/dictionary | D30: ADMIN cria novo termo com sucesso | E30: Funcional | F30: Alta | G30: ADMIN | H30: ADMIN autenticado. | I30: 1. Chamar POST /api/dictionary com termo, definição e categoria. | J30: { term, definition, category }. | K30: HTTP 201; termo criado em estado pendente de aprovação. | L30: Manual | M30: A executar
A31: CT-030 | B31: Dicionário de Termos | C31: POST /api/dictionary | D31: Criação valida campos obrigatórios antes de persistir | E31: Funcional | F31: Alta | G31: ADMIN | H31: ADMIN autenticado. | I31: 1. Enviar payload sem campos obrigatórios (ex.: sem "term"). | J31: Payload incompleto. | K31: HTTP 400/422 com mensagem de validação; nenhum registro é criado. | L31: server/tests/critical_routes.unit.test.ts | M31: A executar
A32: CT-031 | B32: Dicionário de Termos | C32: PUT /api/dictionary/:id | D32: Atualização rejeita payload vazio sem consultar o termo | E32: Funcional | F32: Média | G32: ADMIN | H32: Termo existente cadastrado. | I32: 1. Chamar PUT /api/dictionary/:id com corpo vazio ou sem campos alteráveis. | J32: Payload vazio {}. | K32: HTTP 400 antes de qualquer consulta ao banco (fail-fast); termo original permanece inalterado. | L32: server/tests/critical_routes.unit.test.ts | M32: A executar
A33: CT-032 | B33: Dicionário de Termos | C33: POST /api/dictionary/:id/approve | D33: Fluxo de aprovação de termo pendente | E33: Funcional | F33: Alta | G33: ADMIN | H33: Termo em estado pendente de aprovação. | I33: 1. Chamar POST /api/dictionary/:id/approve. | J33: ID de termo pendente. | K33: HTTP 200; termo passa para estado aprovado, ainda não publicado. | L33: Manual | M33: A executar
A34: CT-033 | B34: Dicionário de Termos | C34: POST /api/dictionary/:id/publish | D34: Publicação de termo o torna ativo e visível no contexto da LIA | E34: Integração | F34: Alta | G34: ADMIN | H34: Termo aprovado; ADMIN autenticado. | I34: 1. Publicar o termo via POST /:id/publish. 2. Consultar GET /api/ai/context. | J34: ID de termo aprovado. | K34: Termo passa a ser a versão ativa e aparece no contexto/prompt injetado para a LIA (ADR 003). | L34: server/tests/knowledge_integration.test.ts | M34: A executar
A35: CT-034 | B35: Dicionário de Termos | C35: POST /api/dictionary/:id/rollback | D35: Rollback sem versão anterior desfaz a transação com segurança | E35: Funcional | F35: Média | G35: ADMIN | H35: Termo publicado sem histórico de versão anterior. | I35: 1. Chamar POST /:id/rollback em termo sem versão anterior. | J35: ID de termo sem histórico. | K35: HTTP 4xx controlado; a transação aberta é revertida e o estado do termo permanece consistente (sem corrupção). | L35: server/tests/critical_routes.unit.test.ts | M35: A executar
A36: CT-035 | B36: Dicionário de Termos | C36: DELETE /api/dictionary/:id | D36: Exclusão de termo restrita a ADMIN | E36: Segurança | F36: Média | G36: ADMIN | H36: Termo existente; usuários OPERADOR/SOLICITANTE e ADMIN disponíveis. | I36: 1. Tentar excluir como OPERADOR (esperar 403). 2. Excluir como ADMIN. | J36: ID de termo existente. | K36: Não-ADMIN recebe 403; ADMIN exclui com sucesso (200/204). | L36: Manual | M36: A executar
A37: CT-036 | B37: Dicionário de Termos | C37: POST /api/dictionary/seed | D37: Seed inicial de termos do dicionário | E37: Funcional | F37: Baixa | G37: ADMIN | H37: Banco de testes vazio ou com dados mínimos. | I37: 1. Chamar POST /api/dictionary/seed como ADMIN. | J37: — | K37: HTTP 200/201; termos padrão são inseridos sem duplicar em execuções repetidas (idempotente). | L37: Manual | M37: A executar
A38: CT-037 | B38: Dicionário de Termos | C38: POST /api/dictionary/:id/publish | D38: Publicação de termo inexistente encerra a transação corretamente | E38: Funcional | F38: Média | G38: ADMIN | H38: ID inexistente no banco. | I38: 1. Chamar POST /api/dictionary/999999/publish. | J38: ID inexistente. | K38: HTTP 404 controlado; conexão/transação é liberada corretamente (sem vazamento de conexão no pool). | L38: server/tests/critical_routes.unit.test.ts | M38: A executar
A39: CT-038 | B39: Normas | C39: GET /api/norms | D39: Listagem pública de normas publicadas | E39: Funcional | F39: Média | G39: Público (sem login) | H39: Normas publicadas existentes. | I39: 1. Chamar GET /api/norms sem autenticação. | J39: — | K39: HTTP 200; lista apenas normas vigentes/publicadas. | L39: Manual | M39: A executar
A40: CT-039 | B40: Normas | C40: PUT /api/norms/:id | D40: ADMIN atualiza norma existente | E40: Funcional | F40: Alta | G40: ADMIN | H40: Norma cadastrada. | I40: 1. Chamar PUT /api/norms/:id alterando texto/seção. | J40: Payload parcial de atualização. | K40: HTTP 200; alterações refletidas em nova versão de rascunho da norma. | L40: Manual | M40: A executar | N40: Sem teste automatizado direto do ciclo publicar/rollback — ver GAP-022.
A41: CT-040 | B41: Normas | C41: PUT /api/norms/:id/applicability | D41: Aplicabilidade aceita null como "todos os tipos de job" | E41: Funcional | F41: Alta | G41: ADMIN | H41: Norma existente. | I41: 1. Enviar escopo de aplicabilidade com valor null. | J41: { jobTypeScope: null }. | K41: HTTP 200; norma passa a se aplicar a todos os tipos de job. | L41: server/tests/norms_applicability.unit.test.ts | M41: A executar
A42: CT-041 | B42: Normas | C42: PUT /api/norms/:id/applicability | D42: Normalização aceita escopo válido de tipos de job | E42: Funcional | F42: Alta | G42: ADMIN | H42: Norma existente; tipos de job válidos cadastrados. | I42: 1. Enviar lista válida de job types no escopo. | J42: { jobTypeScope: ["UNIX", "WINDOWS"] }. | K42: HTTP 200; escopo normalizado e persistido corretamente. | L42: server/tests/norms_applicability.unit.test.ts | M42: A executar
A43: CT-042 | B43: Normas | C43: PUT /api/norms/:id/applicability | D43: Escopo com valores inseguros/inválidos é rejeitado | E43: Segurança | F43: Alta | G43: ADMIN | H43: Norma existente. | I43: 1. Enviar valores fora do domínio permitido ou com payload malicioso no escopo. | J43: { jobTypeScope: ["<script>", "TIPO_INEXISTENTE"] }. | K43: HTTP 400/422; nenhuma alteração é persistida. | L43: server/tests/norms_applicability.unit.test.ts | M43: A executar
A44: CT-043 | B44: Normas | C44: approve / publish / rollback | D44: Fluxo completo de versionamento de norma (aprovar, publicar, reverter) | E44: Integração | F44: Alta | G44: ADMIN | H44: Norma em rascunho. | I44: 1. Aprovar a norma. 2. Publicar a norma. 3. Editar novamente e publicar nova versão. 4. Executar rollback para a versão anterior. | J44: Sequência de chamadas aprovar → publicar → nova edição → rollback. | K44: Cada etapa retorna 200; após rollback, a versão anterior volta a ser a ativa e o histórico de versões é preservado. | L44: Manual | M44: A executar | N44: Sem teste automatizado direto — ver GAP-022.
A45: CT-044 | B45: Normas | C45: DELETE /api/norms/:id | D45: Exclusão de norma restrita a ADMIN | E45: Segurança | F45: Média | G45: ADMIN | H45: Norma existente. | I45: 1. Tentar excluir como OPERADOR (esperar 403). 2. Excluir como ADMIN. | J45: ID de norma existente. | K45: Não-ADMIN recebe 403; ADMIN exclui com sucesso. | L45: Manual | M45: A executar
A46: CT-045 | B46: Normas | C46: POST /api/norms/seed | D46: Seed inicial de normas | E46: Funcional | F46: Baixa | G46: ADMIN | H46: Banco de testes vazio ou com dados mínimos. | I46: 1. Chamar POST /api/norms/seed como ADMIN. | J46: — | K46: HTTP 200/201; normas padrão inseridas de forma idempotente. | L46: Manual | M46: A executar
...

Sheet Matriz de Cobertura por Arquivo
A1: ID | B1: Arquivo | C1: Camada | D1: Criticidade | E1: Teste Direto? | F1: Evidência Localizada | G1: Linhas | H1: Cobertas | I1: Cob. Linhas | J1: Cob. Branches | K1: Cob. Funções | L1: Situação | M1: Observação / Ação
A2: 1 | B2: server/app.ts | C2: Backend / Infraestrutura | D2: P1 | E2: Indireto | F2: server/tests/critical_routes.unit.test.ts | G2: 42 | H2: 39 | I2: 0.9285 | J2: 0 | K2: 1 | L2: Coberto | M2: Manter suíte e cobrir branches remanescentes.
A3: 2 | B3: server/db.ts | C3: Backend / Infraestrutura | D3: P1 | E3: Indireto | F3: carregado indiretamente pela aplicação | G3: 10 | H3: 8 | I3: 0.8 | J3: 0 | K3: 1 | L3: Coberto | M3: Manter suíte e cobrir branches remanescentes.
A4: 3 | B4: server/index.ts | C4: Backend / Infraestrutura | D4: P1 | E4: Não | F4: Nenhum teste localizado | G4: 8 | H4: 0 | I4: 0 | J4: 0 | K4: 0 | L4: Sem cobertura | M4: Criar testes unitários ou de componente dedicados.
A5: 4 | B5: server/migrate.ts | C5: Backend / Infraestrutura | D5: P1 | E5: Não | F5: Nenhum teste localizado | G5: 189 | H5: 0 | I5: 0 | J5: 0 | K5: 0 | L5: Sem cobertura | M5: Criar testes unitários ou de componente dedicados. Ver GAP-018.
A6: 5 | B6: server/migrationSafety.ts | C6: Backend / Infraestrutura | D6: P1 | E6: Sim | F6: server/tests/migrationSafety.test.ts | G6: 270 | H6: 197 | I6: 0.7296 | J6: 0.8947 | K6: 0.6666 | L6: Parcial | M6: Cobertura insuficiente; ampliar caminhos felizes, erros e autorização.
A7: 6 | B7: server/middleware/auth.ts | C7: Backend / Middleware | D7: P0 | E7: Indireto | F7: server/tests/critical_routes.unit.test.ts | G7: 116 | H7: 58 | I7: 0.5 | J7: 0.7333 | K7: 0.6 | L7: Parcial | M7: Cobertura insuficiente; ampliar caminhos felizes, erros e autorização. Ver GAP-008/GAP-009.
A8: 7 | B8: server/routes/ai.ts | C8: Backend / Rotas | D8: P0 | E8: Indireto | F8: carregado ao importar server/app.ts | G8: 525 | H8: 114 | I8: 0.2171 | J8: 1 | K8: 0.2307 | L8: Parcial | M8: Cobertura insuficiente; ampliar caminhos felizes, erros e autorização. Ver GAP-012/GAP-013.
A9: 8 | B9: server/routes/applicationChecklists.ts | C9: Backend / Rotas | D9: P1 | E9: Sim | F9: server/tests/critical_routes.unit.test.ts | G9: 261 | H9: 101 | I9: 0.3869 | J9: 0.4285 | K9: 0.2857 | L9: Parcial | M9: Cobertura insuficiente; ampliar caminhos felizes, erros e autorização. Ver GAP-025.
A10: 9 | B10: server/routes/auth.ts | C10: Backend / Rotas | D10: P0 | E10: Indireto | F10: carregado ao importar server/app.ts | G10: 207 | H10: 25 | I10: 0.1207 | J10: 1 | K10: 1 | L10: Parcial | M10: Cobertura insuficiente; ampliar caminhos felizes, erros e autorização. Ver GAP-010/GAP-011.
A11: 10 | B11: server/routes/checklistCatalog.ts | C11: Backend / Rotas | D11: P1 | E11: Sim | F11: server/tests/critical_routes.unit.test.ts | G11: 267 | H11: 99 | I11: 0.3707 | J11: 0.44 | K11: 1 | L11: Parcial | M11: Cobertura insuficiente; ampliar caminhos felizes, erros e autorização. Ver GAP-024.
A12: 11 | B12: server/routes/checklists.ts | C12: Backend / Rotas | D12: P0 | E12: Indireto | F12: server/tests/pdf.test.ts (2 casos ignorados sem BD) | G12: 515 | H12: 20 | I12: 0.0388 | J12: 1 | K12: 0 | L12: Parcial | M12: Cobertura insuficiente; ampliar caminhos felizes, erros e autorização. Ver GAP-001 a GAP-004.
A13: 12 | B13: server/routes/dictionary.ts | C13: Backend / Rotas | D13: P1 | E13: Sim | F13: server/tests/critical_routes.unit.test.ts | G13: 213 | H13: 98 | I13: 0.46 | J13: 0.375 | K13: 1 | L13: Parcial | M13: Cobertura insuficiente; ampliar caminhos felizes, erros e autorização. Ver GAP-023.
... A47: 46 | B47: src/utils/validationPresentation.ts | C47: Frontend / Utilitários | D47: P1 | E47: Sim | F47: src/utils/validationPresentation.test.ts | G47: 23 | H47: 22 | I47: 0.9565 | J47: 0.6666 | K47: 1 | L47: Coberto | M47: Manter suíte e cobrir branches remanescentes.

Sheet Lacunas de Testes Unitários
A1: ID | B1: Prioridade | C1: Camada | D1: Módulo | E1: Função / Rota | F1: Cenário | G1: Pré-condições / Mocks | H1: Passos / Entrada | I1: Resultado Esperado | J1: Tipo Sugerido | K1: Arquivo de Teste Sugerido | L1: Status
A2: GAP-001 | B2: P0 | C2: Backend / Rotas | D2: server/routes/checklists.ts | E2: GET /api/checklists | F2: isolar dados por papel e impedir filtro de terceiro | G2: JWTs de SOLICITANTE e OPERADOR; pool mockado | H2: consultar com cada papel e filtro user_id | I2: SOLICITANTE vê somente próprios registros; OPERADOR segue política | J2: Unitário com supertest | K2: server/tests/checklists.unit.test.ts | L2: Pendente
A3: GAP-002 | B3: P0 | C3: Backend / Rotas | D3: server/routes/checklists.ts | E3: POST /api/checklists | F3: derivar user_id do JWT e ignorar valor do payload | G3: usuário autenticado; validação mockada | H3: enviar user_id de terceiro no corpo | I3: persistência usa somente o usuário autenticado | J3: Unitário com supertest | K3: server/tests/checklists.unit.test.ts | L3: Pendente
A4: GAP-003 | B4: P0 | C4: Backend / Rotas | D4: server/routes/checklists.ts | E4: POST /api/checklists | F4: tratar validação bloqueante e status final | G4: motor mockado com erros bloqueantes | H4: criar checklist inválido | I4: retorna erro controlado e não confirma transação indevida | J4: Unitário com supertest | K4: server/tests/checklists.unit.test.ts | L4: Pendente
A5: GAP-004 | B5: P0 | C5: Backend / Rotas | D5: server/routes/checklists.ts | E5: GET /:id/pdf | F5: autorizar proprietário e bloquear terceiro | G5: BD/pool e pdfService mockados | H5: baixar PDF próprio e de terceiro | I5: 200 para proprietário; 403/404 para terceiro | J5: Unitário com mocks | K5: server/tests/checklists.unit.test.ts | L5: Pendente
A6: GAP-005 | B6: P0 | C6: Backend / Serviços | D6: server/services/validationEngine.ts | E6: validateChecklist | F6: sem regras publicadas | G6: pool retorna catálogo vazio | H6: validar payload mínimo | I6: resultado previsível sem falso bloqueio; aviso explícito quando aplicável | J6: Unitário | K6: server/tests/validationEngine.unit.test.ts | L6: Pendente
A7: GAP-006 | B7: P0 | C7: Backend / Serviços | D7: server/services/validationEngine.ts | E7: validateChecklist | F7: regras required, regex e dependência | G7: regras mockadas por tipo | H7: testar valor válido, ausente e incompatível | I7: erros têm código, campo, severidade e mensagem corretos | J7: Unitário parametrizado | K7: server/tests/validationEngine.unit.test.ts | L7: Pendente
A8: GAP-007 | B8: P0 | C8: Backend / Serviços | D8: server/services/validationEngine.ts | E8: validateApplicationChecklist | F8: múltiplos jobs e nomes duplicados | G8: catálogo e regras mockados | H8: validar aplicação com 2+ jobs | I8: agrega erros com prefixo por job e preserva ordem | J8: Unitário | K8: server/tests/validationEngine.unit.test.ts | L8: Pendente
A9: GAP-008 | B9: P0 | C9: Backend / Middleware | D9: server/middleware/auth.ts | E9: requireAuth | F9: token ausente, malformado, expirado e usuário inativo | G9: JWT/pool mockados | H9: executar middleware em cada condição | I9: 401 consistente; next somente para token e usuário válidos | J9: Unitário | K9: server/tests/authMiddleware.unit.test.ts | L9: Pendente
A10: GAP-009 | B10: P0 | C10: Backend / Middleware | D10: server/middleware/auth.ts | E10: requireRole / requireOwnership | F10: matriz ADMIN, OPERADOR, SOLICITANTE e recurso alheio | G10: requisições mockadas | H10: variar papel e proprietário | I10: 403 para combinações proibidas; next para permitidas | J10: Unitário parametrizado | K10: server/tests/authMiddleware.unit.test.ts | L10: Pendente
A11: GAP-010 | B11: P0 | C11: Backend / Rotas | D11: server/routes/auth.ts | E11: POST /login | F11: credenciais ausentes, senha inválida e usuário inativo | G11: bcrypt/JWT/pool mockados | H11: executar três falhas e um sucesso | I11: 401/400 sem revelar qual credencial falhou; tokens no sucesso | J11: Unitário com supertest | K11: server/tests/auth.unit.test.ts | L11: Pendente
A12: GAP-011 | B12: P0 | C12: Backend / Rotas | D12: server/routes/auth.ts | E12: POST /refresh e /logout | F12: refresh expirado, revogado, reutilizado e logout | G12: tokens/pool mockados | H12: executar ciclo e tentativas de reuso | I12: rotação/revogação consistente e transação encerrada | J12: Unitário com supertest | K12: server/tests/auth.unit.test.ts | L12: Pendente
... A37: GAP-036 | B37: P2 | C37: Frontend / Componentes | D37: src/components/KnowledgeViews.tsx | E37: dicionário/normas/jobs | F37: permissões, filtros e erros CRUD | G37: serviços/Auth mockados | H37: variar papel e operações | I37: ações disponíveis somente ao papel correto | J37: Teste de componente | K37: src/components/KnowledgeViews.test.tsx | L37: Pendente

Sheet Resumo
B2: Resumo do Plano de Testes
B4: Total de casos de teste | C4: =COUNTA('Casos de Teste'!A2:A158)
B6: Casos por Módulo | E6: Casos por Tipo
B7: Autenticação | C7: =COUNTIF('Casos de Teste'!$B$2:$B$158,B7) | E7: Funcional | F7: =COUNTIF('Casos de Teste'!$E$2:$E$158,E7)
B8: RBAC / Autorização | C8: =COUNTIF('Casos de Teste'!$B$2:$B$158,B8) | E8: Segurança | F8: =COUNTIF('Casos de Teste'!$E$2:$E$158,E8)
B9: Usuários | C9: =COUNTIF('Casos de Teste'!$B$2:$B$158,B9) | E9: Integração | F9: =COUNTIF('Casos de Teste'!$E$2:$E$158,E9)
B10: Dicionário de Termos | C10: =COUNTIF('Casos de Teste'!$B$2:$B$158,B10) | E10: Unitário | F10: =COUNTIF('Casos de Teste'!$E$2:$E$158,E10)
B11: Normas | C11: =COUNTIF('Casos de Teste'!$B$2:$B$158,B11)
B12: Motor de Validação (N/PD/004/02) | C12: =COUNTIF('Casos de Teste'!$B$2:$B$158,B12)
B13: Checklists | C13: =COUNTIF('Casos de Teste'!$B$2:$B$158,B13)
B14: Checklist de Application (v2) | C14: =COUNTIF('Casos de Teste'!$B$2:$B$158,B14)
B15: Catálogo de Checklist | C15: =COUNTIF('Casos de Teste'!$B$2:$B$158,B15)
B16: LIA (Assistente de IA) | C16: =COUNTIF('Casos de Teste'!$B$2:$B$158,B16)
B17: Prompts do Sistema | C17: =COUNTIF('Casos de Teste'!$B$2:$B$158,B17)
B18: Interações, Feedback e Auditoria | C18: =COUNTIF('Casos de Teste'!$B$2:$B$158,B18)
B19: Jobs (tipos e parâmetros) | C19: =COUNTIF('Casos de Teste'!$B$2:$B$158,B19)
B20: Geração de PDF | C20: =COUNTIF('Casos de Teste'!$B$2:$B$158,B20)
B21: Migrações e Segurança de Schema | C21: =COUNTIF('Casos de Teste'!$B$2:$B$158,B21)
B22: Interface (Frontend) | C22: =COUNTIF('Casos de Teste'!$B$2:$B$158,B22)
B23: Health Check e Infraestrutura | C23: =COUNTIF('Casos de Teste'!$B$2:$B$158,B23)
B26: Casos por Prioridade
B27: Alta | C27: =COUNTIF('Casos de Teste'!$F$2:$F$158,B27)
B28: Média | C28: =COUNTIF('Casos de Teste'!$F$2:$F$158,B28)
B29: Baixa | C29: =COUNTIF('Casos de Teste'!$F$2:$F$158,B29)
B32: Cobertura Automatizada (casos deste plano)
B33: Casos com teste automatizado de referência | C33: =COUNTIF('Casos de Teste'!$L$2:$L$158,"*test*")
B34: Casos apenas manuais/exploratórios | C34: =COUNTIF('Casos de Teste'!$L$2:$L$158,"Manual*")
B36: Cobertura de Código Medida (auditoria 07/08/2026)
B37: Cobertura global de linhas/statements | C37: 0.2014
B38: Cobertura global de branches | C38: 0.5909
B39: Cobertura global de funções | C39: 0.5081
B41: Arquivos "Coberto" (≥80% linhas) — de 46 | C41: =COUNTIF('Matriz de Cobertura por Arquivo'!$L$2:$L$47,"Coberto")
B42: Arquivos "Parcial" — de 46 | C42: =COUNTIF('Matriz de Cobertura por Arquivo'!$L$2:$L$47,"Parcial")
B43: Arquivos "Sem cobertura" — de 46 | C43: =COUNTIF('Matriz de Cobertura por Arquivo'!$L$2:$L$47,"Sem cobertura")
B45: Lacunas de Testes Unitários por Prioridade
B46: P0 | C46: =COUNTIF('Lacunas de Testes Unitários'!$B$2:$B$37,B46)
B47: P1 | C47: =COUNTIF('Lacunas de Testes Unitários'!$B$2:$B$37,B47)
B48: P2 | C48: =COUNTIF('Lacunas de Testes Unitários'!$B$2:$B$37,B48)
B49: Total de lacunas priorizadas | C49: =COUNTA('Lacunas de Testes Unitários'!A2:A37)

Sheet Não Funcionais
A1: ID | B1: Categoria | C1: Requisito | D1: Critério de Aceite | E1: Método de Verificação | F1: Prioridade
A2: NF-001 | B2: Segurança | C2: Senhas armazenadas com hashing forte (bcryptjs) | D2: Nenhuma senha em texto plano é gravada no banco em nenhuma tabela. | E2: Inspeção do schema/dados de teste após signup e criação de usuário. | F2: Alta
A3: NF-002 | B3: Segurança | C3: Tokens JWT possuem expiração e refresh tokens são revogáveis | D3: Access token expira dentro do tempo configurado; refresh token pode ser revogado no logout. | E3: server/tests/auth_cycle.test.ts + inspeção de payload do JWT. | F3: Alta
A4: NF-003 | B4: Segurança | C4: Todas as queries usam parametrização (proteção contra SQL Injection) | D4: Tentativas de injeção via campos de texto (nome, termo, filtros) não alteram o comportamento da query. | E4: Casos exploratórios manuais em campos de busca/formulário e revisão de código (uso de pg parametrizado). | F4: Alta
A5: NF-004 | B5: Segurança | C5: RBAC aplicado de forma consistente em 100% das rotas administrativas | D5: Nenhuma rota que altera dados de norma/dicionário/catálogo/usuário é acessível por papel não autorizado. | E5: server/tests/rbac.test.ts + varredura manual de rotas do server/routes. | F5: Alta
A6: NF-005 | B6: Segurança | C6: Auditoria imutável de ações sensíveis | D6: Registros em JobsIA_audit_logs não podem ser alterados/excluídos por rota de API. | E6: Tentativa manual de PUT/DELETE sobre registros de auditoria (esperado: sem rota disponível). | F6: Média
A7: NF-006 | B7: Desempenho | C7: Tempo de resposta de endpoints críticos | D7: GET /api/checklists, POST /api/validate-checklist e POST /api/checklists/application respondem em até 2s sob carga de teste com massa representativa. | E7: Medição manual (ex.: cURL/Insomnia) com massa de ~500 checklists no banco de testes. | F7: Média
A8: NF-007 | B8: Desempenho | C8: Geração de PDF sob checklist extenso | D8: PDF de um checklist de Application com múltiplos jobs e validação extensa é gerado em até 5s. | E8: server/tests/pdf.test.ts (cenário de overflow) + medição manual de tempo. | F8: Média
A9: NF-008 | B9: Desempenho | C9: Resposta do chat da LIA | D9: Tempo até o primeiro byte de resposta do gateway de IA é aceitável para uso conversacional (sem timeout do cliente). | E9: Teste manual exploratório na tela do Agente. | F9: Baixa
A10: NF-009 | B10: Confiabilidade | C10: Suítes automatizadas passam de forma consistente no CI | D10: "npm test", "npm run test:integration" e "npm run test:coverage" concluem sem falha no workflow .github/workflows/test.yml. | E10: Execução do pipeline de CI a cada pull request. | F10: Alta
A11: NF-010 | B11: Confiabilidade | C11: Cobertura de código não regride abaixo do baseline bloqueante | D11: c8 --check-coverage aprova com lines≥19%, statements≥19%, branches≥55%, functions≥45%. Medição real em 07/08/2026: 20,14%/20,14%/59,09%/50,81% — acima do baseline, porém com 23 de 46 arquivos ainda em 0% (ver aba "Matriz de Cobertura por Arquivo"). | E11: "npm run test:coverage". | F11: Alta
A12: NF-011 | B12: Confiabilidade | C12: Deploy em produção preserva o volume e a tabela public.users | D12: Contagem de usuários antes e depois do deploy é idêntica; migrations bloqueiam operações destrutivas em public.users. | E12: server/tests/migrationSafety.test.ts + procedimento manual descrito no README. | F12: Alta
... A19: NF-018 | B19: Confiabilidade | C19: Backlog de testes unitários P0 fechado antes do próximo release | D19: Os 17 itens de Prioridade P0 da aba "Lacunas de Testes Unitários" (auth, RBAC, validationEngine, checklists.ts, ai.ts, api.ts, AuthContext, ProtectedRoute, pdfGenerator) têm teste automatizado implementado. | E19: Revisão da aba "Lacunas de Testes Unitários" + execução de "npm run test:coverage" por arquivo. | F19: Alta

Sheet Rastreabilidade
A1: Referência | B1: Descrição | C1: Casos de Teste / Itens relacionados
A2: ADR 001 | B2: Migração para autenticação própria (Custom Auth / JWT local, bcryptjs, refresh_tokens). | C2: CT-001 a CT-010
A3: ADR 002 | B3: Motor de validação determinístico da norma N/PD/004/02, acionado de forma síncrona antes de salvar/gerar PDF. | C3: CT-048 a CT-072
A4: ADR 003 | B4: Gerenciamento dinâmico de dicionário e normas; apenas conteúdo publicado é injetado no prompt da LIA. | C4: CT-028 a CT-047, CT-107
A5: Norma 5.1.1 | B5: Nomenclatura de arquivos Unix (com exceções de Shell Script e JAR). | C5: CT-048 a CT-054
A6: Norma 5.1.2 | B6: Nomenclatura de arquivos Windows. | C6: CT-055
A7: Norma 5.1.3 | B7: Nomenclatura de arquivos Mainframe. | C7: CT-056
A8: Norma 5.2 / 5.2.1 | B8: Objeto procedural SQL e nome do objeto. | C8: CT-057, CT-058
A9: Norma 5.3.1 / 5.3.2 | B9: Fita magnética Windows/Unix e Unix (banco de dados). | C9: CT-059, CT-060
A10: Norma 5.4.1 / 5.4.2 | B10: Connect:Direct de envio e recebimento. | C10: CT-061, CT-062
A11: Checklist v2 (Application) | B11: Application com múltiplos jobs, ponte, genérico, agendamento e catálogo oficial DIOT. | C11: CT-081 a CT-097
A12: RBAC (README §Matriz de Escopo) | B12: Papéis ADMIN, OPERADOR e SOLICITANTE com middlewares de segurança no backend. | C12: CT-011 a CT-024
... A24: GAP-031 a GAP-036 (P2) | B24: Backlog P2: páginas e componentes React de menor criticidade (LoginPage, SignupPage, HistoryView, KnowledgeViews) sem teste de componente. | C24: CT-138, CT-139, CT-145, CT-146

Sheet Ambiente e Massa de Dados
A1: Item | B1: Descrição
A2: Backend | B2: Express.js/TypeScript executado via "npm run server", disponível em http://localhost:3001.
A3: Frontend | B3: React/Vite executado via "npm run dev", disponível em http://localhost:3000.
A4: Banco de dados de testes | B4: PostgreSQL 14+ dedicado, nunca reaproveitando DATABASE_URL de produção; string informada em DATABASE_URL_TEST.
A5: Setup do schema de testes | B5: JOBSIA_ALLOW_DESTRUCTIVE_SCHEMA_TEST=1 DATABASE_URL_TEST=... npm run test:schema (destrutivo; exige nome do banco com marcador de teste).
A6: Variáveis de ambiente obrigatórias | B6: DATABASE_URL, JWT_SECRET, VITE_API_URL, CORS_ORIGIN (ver .env.example).
A7: Suíte unitária | B7: "npm test" / "npm run test:unit" — não depende de PostgreSQL real.
A8: Suíte de integração | B8: "npm run test:integration" (DATABASE_URL_TEST obrigatória).
A9: Suíte de cobertura | B9: "npm run test:coverage" — c8 com baseline mínimo (lines 19%, statements 19%, branches 55%, functions 45%).
A10: Suítes segmentadas | B10: "npm run test:rbac", "npm run test:validation", "npm run test:security", "npm run test:interaction", "npm run test:jobs", "npm run test:system-prompts".
A11: CI/CD | B11: Workflow ".github/workflows/test.yml" provisiona PostgreSQL efêmero e roda schema, integração, cobertura, build e checagem de tipos.
A12: Usuário de teste — ADMIN | B12: Conta promovida via UPDATE users SET role='ADMIN' (ver README) — usada para casos de administração, catálogo e auditoria.
... A20: Mocks para o backlog de testes unitários | B20: Os itens da aba "Lacunas de Testes Unitários" dependem de dublês determinísticos: pool do pg, bcrypt/JWT, cliente GenAI (LIA) e, no frontend, fetch/localStorage/URL — sem acesso a banco, provedor de IA real ou armazenamento do navegador.
